<?xml version="1.0" encoding="utf-8"?>
<!-- This URDF was automatically created by SolidWorks to URDF Exporter! Originally created by Stephen Brawner (brawner@gmail.com) 
     Commit Version: 1.5.1-0-g916b5db  Build Version: 1.5.7152.31018
     For more information, please see http://wiki.ros.org/sw_urdf_exporter -->
<robot
  name="gripper_urdf">

  <link
    name="base_link">
    <inertial>
      <origin
        xyz="0.00021624 -0.040234 -0.0069938"
        rpy="0 0 0" />
      <mass
        value="0.28445" />
      <inertia
        ixx="0.00029735"
        ixy="-2.8536E-06"
        ixz="-5.3116E-09"
        iyy="0.00015844"
        iyz="-1.2155E-05"
        izz="0.00036539" />
    </inertial>
    <visual>
      <origin
        xyz="0 0 0"
        rpy="0 0 0" />
      <geometry>
        <mesh
          filename="package://gripper_urdf/meshes/base_link.STL" />
      </geometry>
      <material
        name="">
        <color
          rgba="1 0.42353 0.3098 1" />
      </material>
    </visual>
    <collision>
      <origin
        xyz="0 0 0"
        rpy="0 0 0" />
      <geometry>
        <mesh
          filename="package://gripper_urdf/meshes/base_link.STL" />
      </geometry>
    </collision>
  </link>
  <link
    name="gripper_1">
    <inertial>
      <origin
        xyz="0.0014935 -0.12244 -0.016352"
        rpy="0 0 0" />
      <mass
        value="0.020256" />
      <inertia
        ixx="6.4964E-06"
        ixy="-6.3521E-08"
        ixz="1.0077E-07"
        iyy="1.3519E-06"
        iyz="-1.3159E-07"
        izz="7.1948E-06" />
    </inertial>
    <visual>
      <origin
        xyz="0 0 0"
        rpy="0 0 0" />
      <geometry>
        <mesh
          filename="package://gripper_urdf/meshes/gripper_1.STL" />
      </geometry>
      <material
        name="">
        <color
          rgba="0.69412 0.098039 0.098039 1" />
      </material>
    </visual>
    <collision>
      <origin
        xyz="0 0 0"
        rpy="0 0 0" />
      <geometry>
        <mesh
          filename="package://gripper_urdf/meshes/gripper_1.STL" />
      </geometry>
    </collision>
  </link>
  <joint
    name="g_joint_1"
    type="prismatic">
    <origin
      xyz="0 0 0"
      rpy="0 0 0" />
    <parent
      link="base_link" />
    <child
      link="gripper_1" />

    <limit
      lower="0"
      upper="0.03"
      effort="100"
      velocity="3" />
  </joint>
  <link
    name="gripper_2">
    <inertial>
      <origin
        xyz="-0.0018182 -0.12413 -0.02152"
        rpy="0 0 0" />
      <mass
        value="0.021464" />
      <inertia
        ixx="7.4096E-06"
        ixy="7.4468E-08"
        ixz="1.0288E-07"
        iyy="1.3868E-06"
        iyz="1.1201E-07"
        izz="8.0959E-06" />
    </inertial>
    <visual>
      <origin
        xyz="0 0 0"
        rpy="0 0 0" />
      <geometry>
        <mesh
          filename="package://gripper_urdf/meshes/gripper_2.STL" />
      </geometry>
      <material
        name="">
        <color
          rgba="0.69412 0.098039 0.098039 1" />
      </material>
    </visual>
    <collision>
      <origin
        xyz="0 0 0"
        rpy="0 0 0" />
      <geometry>
        <mesh
          filename="package://gripper_urdf/meshes/gripper_2.STL" />
      </geometry>
    </collision>
  </link>
  <joint
    name="g_joint2"
    type="prismatic">
    <origin
      xyz="0 0 0"
      rpy="0 0 0" />
    <parent
      link="base_link" />
    <child
      link="gripper_2" />

    <limit
      lower="-0.03"
      upper="0"
      effort="100"
      velocity="3" />
  </joint>

  
</robot>